<?xml version="1.0" encoding="utf-8"?>
<!-- =================================================================================== -->
<!-- |    This document was autogenerated by xacro from dronecase_test.xacro           | -->
<!-- |    EDITING THIS FILE BY HAND IS NOT RECOMMENDED                                 | -->
<!-- =================================================================================== -->
<robot name="dronecase">
  <!-- dronecase test -->
  <link name="base_link"/>
  <joint name="basic_cuboid_joint" type="fixed">
    <origin rpy="0.0 0.0 0.0" xyz="0.0 0.0 0.05"/>
    <parent link="base_link"/>
    <child link="basic_cuboid_link"/>
  </joint>
  <link name="basic_cuboid_link">
    <!-- inertia settings -->
    <inertial>
      <origin rpy="0.0 0.0 0.0" xyz="0.0 0.0 0.0"/>
      <mass value="250.0"/>
      <inertia ixx="130.416666667" ixy="0.0" ixz="0.0" iyy="21.0416666667" iyz="0.0" izz="151.041666667"/>
    </inertial>
    <visual name="basic_cuboid_link_visual">
      <origin rpy="0.0 0.0 0.0" xyz="0.0 0.0 0.0"/>
      <geometry>
        <box size="1.0 2.5 0.1"/>
      </geometry>
      <material name="basic_cuboid_link_material">
        <color rgba="1.0 0.0 0.0 1.0"/>
        <!-- <texture filename=""/> -->
      </material>
    </visual>
    <collision>
      <origin rpy="0.0 0.0 0.0" xyz="0.0 0.0 0.0"/>
      <geometry>
        <box size="1.0 2.5 0.1"/>
      </geometry>
    </collision>
  </link>
  <joint name="other_cuboid_xp_joint" type="fixed">
    <origin rpy="0.0 0.0 1.57" xyz="0.45 0.0 0.7"/>
    <parent link="basic_cuboid_link"/>
    <child link="other_cuboid_xp_link"/>
  </joint>
  <link name="other_cuboid_xp_link">
    <!-- inertia settings -->
    <inertial>
      <origin rpy="0.0 0.0 0.0" xyz="0.0 0.0 0.0"/>
      <mass value="299.0"/>
      <inertia ixx="42.3583333333" ixy="0.0" ixz="0.0" iyy="173.918333333" iyz="0.0" izz="132.058333333"/>
    </inertial>
    <visual name="other_cuboid_xp_visual">
      <origin rpy="0.0 0.0 0.0" xyz="0.0 0.0 0.0"/>
      <geometry>
        <box size="2.3 0.1 1.3"/>
      </geometry>
      <material name="other_cuboid_xp_material">
        <color rgba="1.0 0.0 0.0 1.0"/>
        <!-- <texture filename=""/> -->
      </material>
    </visual>
    <collision>
      <origin rpy="0.0 0.0 0.0" xyz="0.0 0.0 0.0"/>
      <geometry>
        <box size="2.3 0.1 1.3"/>
      </geometry>
    </collision>
  </link>
  <joint name="other_cuboid_xn_joint" type="fixed">
    <origin rpy="0.0 0.0 -1.57" xyz="-0.45 0.0 0.7"/>
    <parent link="basic_cuboid_link"/>
    <child link="other_cuboid_xn_link"/>
  </joint>
  <link name="other_cuboid_xn_link">
    <!-- inertia settings -->
    <inertial>
      <origin rpy="0.0 0.0 0.0" xyz="0.0 0.0 0.0"/>
      <mass value="299.0"/>
      <inertia ixx="42.3583333333" ixy="0.0" ixz="0.0" iyy="173.918333333" iyz="0.0" izz="132.058333333"/>
    </inertial>
    <visual name="other_cuboid_xn_visual">
      <origin rpy="0.0 0.0 0.0" xyz="0.0 0.0 0.0"/>
      <geometry>
        <box size="2.3 0.1 1.3"/>
      </geometry>
      <material name="other_cuboid_xn_material">
        <color rgba="1.0 0.0 0.0 1.0"/>
        <!-- <texture filename=""/> -->
      </material>
    </visual>
    <collision>
      <origin rpy="0.0 0.0 0.0" xyz="0.0 0.0 0.0"/>
      <geometry>
        <box size="2.3 0.1 1.3"/>
      </geometry>
    </collision>
  </link>
  <joint name="other_cuboid_yp_joint" type="fixed">
    <origin rpy="0.0 0.0 0.0" xyz="0.0 1.2 0.7"/>
    <parent link="basic_cuboid_link"/>
    <child link="other_cuboid_yp_link"/>
  </joint>
  <link name="other_cuboid_yp_link">
    <!-- inertia settings -->
    <inertial>
      <origin rpy="0.0 0.0 0.0" xyz="0.0 0.0 0.0"/>
      <mass value="130.0"/>
      <inertia ixx="18.4166666667" ixy="0.0" ixz="0.0" iyy="29.1416666667" iyz="0.0" izz="10.9416666667"/>
    </inertial>
    <visual name="other_cuboid_yp_visual">
      <origin rpy="0.0 0.0 0.0" xyz="0.0 0.0 0.0"/>
      <geometry>
        <box size="1.0 0.1 1.3"/>
      </geometry>
      <material name="other_cuboid_yp_material">
        <color rgba="1.0 0.0 0.0 1.0"/>
        <!-- <texture filename=""/> -->
      </material>
    </visual>
    <collision>
      <origin rpy="0.0 0.0 0.0" xyz="0.0 0.0 0.0"/>
      <geometry>
        <box size="1.0 0.1 1.3"/>
      </geometry>
    </collision>
  </link>
  <joint name="other_cuboid_yn_joint" type="fixed">
    <origin rpy="0.0 0.0 0.0" xyz="0.0 -1.2 0.7"/>
    <parent link="basic_cuboid_link"/>
    <child link="other_cuboid_yn_link"/>
  </joint>
  <link name="other_cuboid_yn_link">
    <!-- inertia settings -->
    <inertial>
      <origin rpy="0.0 0.0 0.0" xyz="0.0 0.0 0.0"/>
      <mass value="130.0"/>
      <inertia ixx="18.4166666667" ixy="0.0" ixz="0.0" iyy="29.1416666667" iyz="0.0" izz="10.9416666667"/>
    </inertial>
    <visual name="other_cuboid_yn_visual">
      <origin rpy="0.0 0.0 0.0" xyz="0.0 0.0 0.0"/>
      <geometry>
        <box size="1.0 0.1 1.3"/>
      </geometry>
      <material name="other_cuboid_yn_material">
        <color rgba="1.0 0.0 0.0 1.0"/>
        <!-- <texture filename=""/> -->
      </material>
    </visual>
    <collision>
      <origin rpy="0.0 0.0 0.0" xyz="0.0 0.0 0.0"/>
      <geometry>
        <box size="1.0 0.1 1.3"/>
      </geometry>
    </collision>
  </link>
  <joint name="top_cuboid_yp_joint" type="prismatic">
    <origin rpy="0.0 0.0 1.57" xyz="0.0 0.625 1.4"/>
    <parent link="basic_cuboid_link"/>
    <child link="top_cuboid_yp_link"/>
    <axis xyz="1.0 0.0 0.0"/>
    <limit effort="30.0" lower="0.0" upper="0.875" velocity="1.0"/>
    <safety_controller k_position="5" k_velocity="20" soft_lower_limit="0.0" soft_upper_limit="0.8125"/>
  </joint>
  <link name="top_cuboid_yp_link">
    <!-- inertia settings -->
    <inertial>
      <origin rpy="0.0 0.0 0.0" xyz="0.0 0.0 0.0"/>
      <mass value="125.0"/>
      <inertia ixx="10.5208333333" ixy="0.0" ixz="0.0" iyy="16.3802083333" iyz="0.0" izz="26.6927083333"/>
    </inertial>
    <visual name="top_cuboid_yp_link_visual">
      <origin rpy="0.0 0.0 0.0" xyz="0.0 0.0 0.0"/>
      <geometry>
        <box size="1.25 1.0 0.1"/>
      </geometry>
      <material name="top_cuboid_yp_link_material">
        <color rgba="1.0 0.0 0.0 1.0"/>
        <!-- <texture filename=""/> -->
      </material>
    </visual>
    <collision>
      <origin rpy="0.0 0.0 0.0" xyz="0.0 0.0 0.0"/>
      <geometry>
        <box size="1.25 1.0 0.1"/>
      </geometry>
    </collision>
  </link>
  <joint name="top_cuboid_yn_joint" type="prismatic">
    <origin rpy="0.0 0.0 -1.57" xyz="0.0 -0.625 1.4"/>
    <parent link="basic_cuboid_link"/>
    <child link="top_cuboid_yn_link"/>
    <axis xyz="1.0 0.0 0.0"/>
    <limit effort="30.0" lower="0.0" upper="0.875" velocity="1.0"/>
    <safety_controller k_position="5" k_velocity="20" soft_lower_limit="0.0" soft_upper_limit="0.8125"/>
  </joint>
  <link name="top_cuboid_yn_link">
    <!-- inertia settings -->
    <inertial>
      <origin rpy="0.0 0.0 0.0" xyz="0.0 0.0 0.0"/>
      <mass value="125.0"/>
      <inertia ixx="10.5208333333" ixy="0.0" ixz="0.0" iyy="16.3802083333" iyz="0.0" izz="26.6927083333"/>
    </inertial>
    <visual name="top_cuboid_yn_link_visual">
      <origin rpy="0.0 0.0 0.0" xyz="0.0 0.0 0.0"/>
      <geometry>
        <box size="1.25 1.0 0.1"/>
      </geometry>
      <material name="top_cuboid_yn_link_material">
        <color rgba="1.0 0.0 0.0 1.0"/>
        <!-- <texture filename=""/> -->
      </material>
    </visual>
    <collision>
      <origin rpy="0.0 0.0 0.0" xyz="0.0 0.0 0.0"/>
      <geometry>
        <box size="1.25 1.0 0.1"/>
      </geometry>
    </collision>
  </link>
  <!-- http://wiki.ros.org/ros_control -->
  <!-- http://gazebosim.org/tutorials/?tut=ros_control -->
  <transmission name="simple_trans">
    <!-- for now Gazebo only implements the following interface: SimpleTransmission-->
    <type>transmission_interface/SimpleTransmission</type>
    <joint name="top_cuboid_yp_joint">
      <!-- Effort/Velocity/Position -->
      <!-- All controllers use the forward_command_controller to send commands to a hardware interface. -->
      <hardwareInterface>EffortJointInterface</hardwareInterface>
    </joint>
    <actuator name="top_cuboid_yp_joint_motor">
      <hardwareInterface>EffortJointInterface</hardwareInterface>
      <mechanicalReductioon>1</mechanicalReductioon>
    </actuator>
  </transmission>
  <!-- http://wiki.ros.org/ros_control -->
  <!-- http://gazebosim.org/tutorials/?tut=ros_control -->
  <transmission name="simple_trans">
    <!-- for now Gazebo only implements the following interface: SimpleTransmission-->
    <type>transmission_interface/SimpleTransmission</type>
    <joint name="top_cuboid_yn_joint">
      <!-- Effort/Velocity/Position -->
      <!-- All controllers use the forward_command_controller to send commands to a hardware interface. -->
      <hardwareInterface>EffortJointInterface</hardwareInterface>
    </joint>
    <actuator name="top_cuboid_yn_joint_motor">
      <hardwareInterface>EffortJointInterface</hardwareInterface>
      <mechanicalReductioon>1</mechanicalReductioon>
    </actuator>
  </transmission>
  <gazebo reference="basic_cuboid_link">
    <material>Gazebo/White</material>
  </gazebo>
  <gazebo reference="other_cuboid_xp_link">
    <material>Gazebo/White</material>
  </gazebo>
  <gazebo reference="other_cuboid_xn_link">
    <material>Gazebo/White</material>
  </gazebo>
  <gazebo reference="other_cuboid_yp_link">
    <material>Gazebo/White</material>
  </gazebo>
  <gazebo reference="other_cuboid_yn_link">
    <material>Gazebo/White</material>
  </gazebo>
  <gazebo reference="top_cuboid_yp_link">
    <material>Gazebo/Gray</material>
  </gazebo>
  <gazebo reference="top_cuboid_yn_link">
    <material>Gazebo/Gray</material>
  </gazebo>
</robot>

